const { login, register } = require('../../controllers/authController.js');
const { User } = require('../../models/user.js');

jest.mock('../../models/user.js', () => ({
  User: {
    findOne: jest.fn(),
    create: jest.fn(),
  },
}));

describe('Auth Controller', () => {
  afterEach(() => {
    jest.clearAllMocks();
  });

  describe('Login', () => {
    it('should return 401 for invalid credentials', async () => {
      const req = {
        body: {
          username: 'testuser',
          password: 'testpassword',
        },
      };
      const res = {
        status: jest.fn().mockReturnThis(),
        json: jest.fn(),
      };
      User.findOne.mockResolvedValue(null);

      await login(req, res);

      expect(res.status).toHaveBeenCalledWith(401);
      expect(res.json).toHaveBeenCalledWith({ message: 'Invalid credentials' });
    });

    it('should return 500 for unexpected error during login', async () => {
      const req = {
        body: {
          username: 'testuser',
          password: 'testpassword',
        },
      };
      const res = {
        status: jest.fn().mockReturnThis(),
        json: jest.fn(),
      };
      User.findOne.mockRejectedValue(new Error('Unexpected error'));

      await login(req, res);

      expect(res.status).toHaveBeenCalledWith(500);
      expect(res.json).toHaveBeenCalledWith({ message: 'An unexpected error occurred during login' });
    });

    // Write more test cases as needed
  });

  // Write similar tests for the registerÂ function
});
